2025-03-19 22:29:30 - asyncio - ERROR - Task exception was never retrieved
future: <Task finished name='Task-6' coro=<Connection.run() done, defined at C:\Users\mohdi\AppData\Local\Packages\PythonSoftwareFoundation.Python.3.11_qbz5n2kfra8p0\LocalCache\local-packages\Python311\site-packages\playwright\_impl\_connection.py:268> exception=NotImplementedError()>
Traceback (most recent call last):
  File "C:\Users\mohdi\AppData\Local\Packages\PythonSoftwareFoundation.Python.3.11_qbz5n2kfra8p0\LocalCache\local-packages\Python311\site-packages\playwright\_impl\_connection.py", line 275, in run
    await self._transport.connect()
  File "C:\Users\mohdi\AppData\Local\Packages\PythonSoftwareFoundation.Python.3.11_qbz5n2kfra8p0\LocalCache\local-packages\Python311\site-packages\playwright\_impl\_transport.py", line 135, in connect
    raise exc
  File "C:\Users\mohdi\AppData\Local\Packages\PythonSoftwareFoundation.Python.3.11_qbz5n2kfra8p0\LocalCache\local-packages\Python311\site-packages\playwright\_impl\_transport.py", line 123, in connect
    self._proc = await asyncio.create_subprocess_exec(
                 ^^^^^^^^^^^^^^^^^^^^^^^^^^^^^^^^^^^^^
  File "C:\Program Files\WindowsApps\PythonSoftwareFoundation.Python.3.11_3.11.2544.0_x64__qbz5n2kfra8p0\Lib\asyncio\subprocess.py", line 223, in create_subprocess_exec
    transport, protocol = await loop.subprocess_exec(
                          ^^^^^^^^^^^^^^^^^^^^^^^^^^^
  File "C:\Program Files\WindowsApps\PythonSoftwareFoundation.Python.3.11_3.11.2544.0_x64__qbz5n2kfra8p0\Lib\asyncio\base_events.py", line 1708, in subprocess_exec
    transport = await self._make_subprocess_transport(
                ^^^^^^^^^^^^^^^^^^^^^^^^^^^^^^^^^^^^^^
  File "C:\Program Files\WindowsApps\PythonSoftwareFoundation.Python.3.11_3.11.2544.0_x64__qbz5n2kfra8p0\Lib\asyncio\base_events.py", line 503, in _make_subprocess_transport
    raise NotImplementedError
NotImplementedError
2025-03-19 22:29:30 - api.routes - ERROR - Error processing URLs: 
2025-03-19 22:29:43 - asyncio - ERROR - Unclosed client session
client_session: <aiohttp.client.ClientSession object at 0x0000014C3A9C45D0>
2025-03-19 22:29:55 - asyncio - ERROR - Task exception was never retrieved
future: <Task finished name='Task-5' coro=<Connection.run() done, defined at C:\Users\mohdi\AppData\Local\Packages\PythonSoftwareFoundation.Python.3.11_qbz5n2kfra8p0\LocalCache\local-packages\Python311\site-packages\playwright\_impl\_connection.py:268> exception=NotImplementedError()>
Traceback (most recent call last):
  File "C:\Users\mohdi\AppData\Local\Packages\PythonSoftwareFoundation.Python.3.11_qbz5n2kfra8p0\LocalCache\local-packages\Python311\site-packages\playwright\_impl\_connection.py", line 275, in run
    await self._transport.connect()
  File "C:\Users\mohdi\AppData\Local\Packages\PythonSoftwareFoundation.Python.3.11_qbz5n2kfra8p0\LocalCache\local-packages\Python311\site-packages\playwright\_impl\_transport.py", line 135, in connect
    raise exc
  File "C:\Users\mohdi\AppData\Local\Packages\PythonSoftwareFoundation.Python.3.11_qbz5n2kfra8p0\LocalCache\local-packages\Python311\site-packages\playwright\_impl\_transport.py", line 123, in connect
    self._proc = await asyncio.create_subprocess_exec(
                 ^^^^^^^^^^^^^^^^^^^^^^^^^^^^^^^^^^^^^
  File "C:\Program Files\WindowsApps\PythonSoftwareFoundation.Python.3.11_3.11.2544.0_x64__qbz5n2kfra8p0\Lib\asyncio\subprocess.py", line 223, in create_subprocess_exec
    transport, protocol = await loop.subprocess_exec(
                          ^^^^^^^^^^^^^^^^^^^^^^^^^^^
  File "C:\Program Files\WindowsApps\PythonSoftwareFoundation.Python.3.11_3.11.2544.0_x64__qbz5n2kfra8p0\Lib\asyncio\base_events.py", line 1708, in subprocess_exec
    transport = await self._make_subprocess_transport(
                ^^^^^^^^^^^^^^^^^^^^^^^^^^^^^^^^^^^^^^
  File "C:\Program Files\WindowsApps\PythonSoftwareFoundation.Python.3.11_3.11.2544.0_x64__qbz5n2kfra8p0\Lib\asyncio\base_events.py", line 503, in _make_subprocess_transport
    raise NotImplementedError
NotImplementedError
2025-03-19 22:29:55 - api.routes - ERROR - Error processing URLs: 
2025-03-19 22:31:37 - asyncio - ERROR - Unclosed client session
client_session: <aiohttp.client.ClientSession object at 0x000001E5F73C21D0>
2025-03-19 22:32:16 - asyncio - ERROR - Task exception was never retrieved
future: <Task finished name='Task-5' coro=<Connection.run() done, defined at C:\Users\mohdi\AppData\Local\Packages\PythonSoftwareFoundation.Python.3.11_qbz5n2kfra8p0\LocalCache\local-packages\Python311\site-packages\playwright\_impl\_connection.py:268> exception=NotImplementedError()>
Traceback (most recent call last):
  File "C:\Users\mohdi\AppData\Local\Packages\PythonSoftwareFoundation.Python.3.11_qbz5n2kfra8p0\LocalCache\local-packages\Python311\site-packages\playwright\_impl\_connection.py", line 275, in run
    await self._transport.connect()
  File "C:\Users\mohdi\AppData\Local\Packages\PythonSoftwareFoundation.Python.3.11_qbz5n2kfra8p0\LocalCache\local-packages\Python311\site-packages\playwright\_impl\_transport.py", line 135, in connect
    raise exc
  File "C:\Users\mohdi\AppData\Local\Packages\PythonSoftwareFoundation.Python.3.11_qbz5n2kfra8p0\LocalCache\local-packages\Python311\site-packages\playwright\_impl\_transport.py", line 123, in connect
    self._proc = await asyncio.create_subprocess_exec(
                 ^^^^^^^^^^^^^^^^^^^^^^^^^^^^^^^^^^^^^
  File "C:\Program Files\WindowsApps\PythonSoftwareFoundation.Python.3.11_3.11.2544.0_x64__qbz5n2kfra8p0\Lib\asyncio\subprocess.py", line 223, in create_subprocess_exec
    transport, protocol = await loop.subprocess_exec(
                          ^^^^^^^^^^^^^^^^^^^^^^^^^^^
  File "C:\Program Files\WindowsApps\PythonSoftwareFoundation.Python.3.11_3.11.2544.0_x64__qbz5n2kfra8p0\Lib\asyncio\base_events.py", line 1708, in subprocess_exec
    transport = await self._make_subprocess_transport(
                ^^^^^^^^^^^^^^^^^^^^^^^^^^^^^^^^^^^^^^
  File "C:\Program Files\WindowsApps\PythonSoftwareFoundation.Python.3.11_3.11.2544.0_x64__qbz5n2kfra8p0\Lib\asyncio\base_events.py", line 503, in _make_subprocess_transport
    raise NotImplementedError
NotImplementedError
2025-03-19 22:32:16 - crawler.crawler - WARNING - Failed to initialize Playwright, falling back to simple HTTP requests: 
2025-03-19 22:32:17 - crawler.crawler - INFO - Using regular HTTP request to crawl https://www.wemark.com.au/
2025-03-19 22:46:51 - asyncio - ERROR - Task exception was never retrieved
future: <Task finished name='Task-6' coro=<Connection.run() done, defined at C:\Users\mohdi\AppData\Local\Packages\PythonSoftwareFoundation.Python.3.11_qbz5n2kfra8p0\LocalCache\local-packages\Python311\site-packages\playwright\_impl\_connection.py:272> exception=NotImplementedError()>
Traceback (most recent call last):
  File "C:\Users\mohdi\AppData\Local\Packages\PythonSoftwareFoundation.Python.3.11_qbz5n2kfra8p0\LocalCache\local-packages\Python311\site-packages\playwright\_impl\_connection.py", line 279, in run
    await self._transport.connect()
  File "C:\Users\mohdi\AppData\Local\Packages\PythonSoftwareFoundation.Python.3.11_qbz5n2kfra8p0\LocalCache\local-packages\Python311\site-packages\playwright\_impl\_transport.py", line 133, in connect
    raise exc
  File "C:\Users\mohdi\AppData\Local\Packages\PythonSoftwareFoundation.Python.3.11_qbz5n2kfra8p0\LocalCache\local-packages\Python311\site-packages\playwright\_impl\_transport.py", line 120, in connect
    self._proc = await asyncio.create_subprocess_exec(
                 ^^^^^^^^^^^^^^^^^^^^^^^^^^^^^^^^^^^^^
  File "C:\Program Files\WindowsApps\PythonSoftwareFoundation.Python.3.11_3.11.2544.0_x64__qbz5n2kfra8p0\Lib\asyncio\subprocess.py", line 223, in create_subprocess_exec
    transport, protocol = await loop.subprocess_exec(
                          ^^^^^^^^^^^^^^^^^^^^^^^^^^^
  File "C:\Program Files\WindowsApps\PythonSoftwareFoundation.Python.3.11_3.11.2544.0_x64__qbz5n2kfra8p0\Lib\asyncio\base_events.py", line 1708, in subprocess_exec
    transport = await self._make_subprocess_transport(
                ^^^^^^^^^^^^^^^^^^^^^^^^^^^^^^^^^^^^^^
  File "C:\Program Files\WindowsApps\PythonSoftwareFoundation.Python.3.11_3.11.2544.0_x64__qbz5n2kfra8p0\Lib\asyncio\base_events.py", line 503, in _make_subprocess_transport
    raise NotImplementedError
NotImplementedError
2025-03-19 22:46:51 - api.routes - ERROR - Error processing URLs: 
2025-03-19 22:47:03 - asyncio - ERROR - Task exception was never retrieved
future: <Task finished name='Task-10' coro=<Connection.run() done, defined at C:\Users\mohdi\AppData\Local\Packages\PythonSoftwareFoundation.Python.3.11_qbz5n2kfra8p0\LocalCache\local-packages\Python311\site-packages\playwright\_impl\_connection.py:272> exception=NotImplementedError()>
Traceback (most recent call last):
  File "C:\Users\mohdi\AppData\Local\Packages\PythonSoftwareFoundation.Python.3.11_qbz5n2kfra8p0\LocalCache\local-packages\Python311\site-packages\playwright\_impl\_connection.py", line 279, in run
    await self._transport.connect()
  File "C:\Users\mohdi\AppData\Local\Packages\PythonSoftwareFoundation.Python.3.11_qbz5n2kfra8p0\LocalCache\local-packages\Python311\site-packages\playwright\_impl\_transport.py", line 133, in connect
    raise exc
  File "C:\Users\mohdi\AppData\Local\Packages\PythonSoftwareFoundation.Python.3.11_qbz5n2kfra8p0\LocalCache\local-packages\Python311\site-packages\playwright\_impl\_transport.py", line 120, in connect
    self._proc = await asyncio.create_subprocess_exec(
                 ^^^^^^^^^^^^^^^^^^^^^^^^^^^^^^^^^^^^^
  File "C:\Program Files\WindowsApps\PythonSoftwareFoundation.Python.3.11_3.11.2544.0_x64__qbz5n2kfra8p0\Lib\asyncio\subprocess.py", line 223, in create_subprocess_exec
    transport, protocol = await loop.subprocess_exec(
                          ^^^^^^^^^^^^^^^^^^^^^^^^^^^
  File "C:\Program Files\WindowsApps\PythonSoftwareFoundation.Python.3.11_3.11.2544.0_x64__qbz5n2kfra8p0\Lib\asyncio\base_events.py", line 1708, in subprocess_exec
    transport = await self._make_subprocess_transport(
                ^^^^^^^^^^^^^^^^^^^^^^^^^^^^^^^^^^^^^^
  File "C:\Program Files\WindowsApps\PythonSoftwareFoundation.Python.3.11_3.11.2544.0_x64__qbz5n2kfra8p0\Lib\asyncio\base_events.py", line 503, in _make_subprocess_transport
    raise NotImplementedError
NotImplementedError
2025-03-19 22:47:03 - api.routes - ERROR - Error processing URLs: 
2025-03-19 22:47:04 - asyncio - ERROR - Task exception was never retrieved
future: <Task finished name='Task-12' coro=<Connection.run() done, defined at C:\Users\mohdi\AppData\Local\Packages\PythonSoftwareFoundation.Python.3.11_qbz5n2kfra8p0\LocalCache\local-packages\Python311\site-packages\playwright\_impl\_connection.py:272> exception=NotImplementedError()>
Traceback (most recent call last):
  File "C:\Users\mohdi\AppData\Local\Packages\PythonSoftwareFoundation.Python.3.11_qbz5n2kfra8p0\LocalCache\local-packages\Python311\site-packages\playwright\_impl\_connection.py", line 279, in run
    await self._transport.connect()
  File "C:\Users\mohdi\AppData\Local\Packages\PythonSoftwareFoundation.Python.3.11_qbz5n2kfra8p0\LocalCache\local-packages\Python311\site-packages\playwright\_impl\_transport.py", line 133, in connect
    raise exc
  File "C:\Users\mohdi\AppData\Local\Packages\PythonSoftwareFoundation.Python.3.11_qbz5n2kfra8p0\LocalCache\local-packages\Python311\site-packages\playwright\_impl\_transport.py", line 120, in connect
    self._proc = await asyncio.create_subprocess_exec(
                 ^^^^^^^^^^^^^^^^^^^^^^^^^^^^^^^^^^^^^
  File "C:\Program Files\WindowsApps\PythonSoftwareFoundation.Python.3.11_3.11.2544.0_x64__qbz5n2kfra8p0\Lib\asyncio\subprocess.py", line 223, in create_subprocess_exec
    transport, protocol = await loop.subprocess_exec(
                          ^^^^^^^^^^^^^^^^^^^^^^^^^^^
  File "C:\Program Files\WindowsApps\PythonSoftwareFoundation.Python.3.11_3.11.2544.0_x64__qbz5n2kfra8p0\Lib\asyncio\base_events.py", line 1708, in subprocess_exec
    transport = await self._make_subprocess_transport(
                ^^^^^^^^^^^^^^^^^^^^^^^^^^^^^^^^^^^^^^
  File "C:\Program Files\WindowsApps\PythonSoftwareFoundation.Python.3.11_3.11.2544.0_x64__qbz5n2kfra8p0\Lib\asyncio\base_events.py", line 503, in _make_subprocess_transport
    raise NotImplementedError
NotImplementedError
2025-03-19 22:47:04 - api.routes - ERROR - Error processing URLs: 
2025-03-19 22:47:05 - asyncio - ERROR - Task exception was never retrieved
future: <Task finished name='Task-14' coro=<Connection.run() done, defined at C:\Users\mohdi\AppData\Local\Packages\PythonSoftwareFoundation.Python.3.11_qbz5n2kfra8p0\LocalCache\local-packages\Python311\site-packages\playwright\_impl\_connection.py:272> exception=NotImplementedError()>
Traceback (most recent call last):
  File "C:\Users\mohdi\AppData\Local\Packages\PythonSoftwareFoundation.Python.3.11_qbz5n2kfra8p0\LocalCache\local-packages\Python311\site-packages\playwright\_impl\_connection.py", line 279, in run
    await self._transport.connect()
  File "C:\Users\mohdi\AppData\Local\Packages\PythonSoftwareFoundation.Python.3.11_qbz5n2kfra8p0\LocalCache\local-packages\Python311\site-packages\playwright\_impl\_transport.py", line 133, in connect
    raise exc
  File "C:\Users\mohdi\AppData\Local\Packages\PythonSoftwareFoundation.Python.3.11_qbz5n2kfra8p0\LocalCache\local-packages\Python311\site-packages\playwright\_impl\_transport.py", line 120, in connect
    self._proc = await asyncio.create_subprocess_exec(
                 ^^^^^^^^^^^^^^^^^^^^^^^^^^^^^^^^^^^^^
  File "C:\Program Files\WindowsApps\PythonSoftwareFoundation.Python.3.11_3.11.2544.0_x64__qbz5n2kfra8p0\Lib\asyncio\subprocess.py", line 223, in create_subprocess_exec
    transport, protocol = await loop.subprocess_exec(
                          ^^^^^^^^^^^^^^^^^^^^^^^^^^^
  File "C:\Program Files\WindowsApps\PythonSoftwareFoundation.Python.3.11_3.11.2544.0_x64__qbz5n2kfra8p0\Lib\asyncio\base_events.py", line 1708, in subprocess_exec
    transport = await self._make_subprocess_transport(
                ^^^^^^^^^^^^^^^^^^^^^^^^^^^^^^^^^^^^^^
  File "C:\Program Files\WindowsApps\PythonSoftwareFoundation.Python.3.11_3.11.2544.0_x64__qbz5n2kfra8p0\Lib\asyncio\base_events.py", line 503, in _make_subprocess_transport
    raise NotImplementedError
NotImplementedError
2025-03-19 22:47:05 - api.routes - ERROR - Error processing URLs: 
2025-03-19 22:47:06 - asyncio - ERROR - Task exception was never retrieved
future: <Task finished name='Task-16' coro=<Connection.run() done, defined at C:\Users\mohdi\AppData\Local\Packages\PythonSoftwareFoundation.Python.3.11_qbz5n2kfra8p0\LocalCache\local-packages\Python311\site-packages\playwright\_impl\_connection.py:272> exception=NotImplementedError()>
Traceback (most recent call last):
  File "C:\Users\mohdi\AppData\Local\Packages\PythonSoftwareFoundation.Python.3.11_qbz5n2kfra8p0\LocalCache\local-packages\Python311\site-packages\playwright\_impl\_connection.py", line 279, in run
    await self._transport.connect()
  File "C:\Users\mohdi\AppData\Local\Packages\PythonSoftwareFoundation.Python.3.11_qbz5n2kfra8p0\LocalCache\local-packages\Python311\site-packages\playwright\_impl\_transport.py", line 133, in connect
    raise exc
  File "C:\Users\mohdi\AppData\Local\Packages\PythonSoftwareFoundation.Python.3.11_qbz5n2kfra8p0\LocalCache\local-packages\Python311\site-packages\playwright\_impl\_transport.py", line 120, in connect
    self._proc = await asyncio.create_subprocess_exec(
                 ^^^^^^^^^^^^^^^^^^^^^^^^^^^^^^^^^^^^^
  File "C:\Program Files\WindowsApps\PythonSoftwareFoundation.Python.3.11_3.11.2544.0_x64__qbz5n2kfra8p0\Lib\asyncio\subprocess.py", line 223, in create_subprocess_exec
    transport, protocol = await loop.subprocess_exec(
                          ^^^^^^^^^^^^^^^^^^^^^^^^^^^
  File "C:\Program Files\WindowsApps\PythonSoftwareFoundation.Python.3.11_3.11.2544.0_x64__qbz5n2kfra8p0\Lib\asyncio\base_events.py", line 1708, in subprocess_exec
    transport = await self._make_subprocess_transport(
                ^^^^^^^^^^^^^^^^^^^^^^^^^^^^^^^^^^^^^^
  File "C:\Program Files\WindowsApps\PythonSoftwareFoundation.Python.3.11_3.11.2544.0_x64__qbz5n2kfra8p0\Lib\asyncio\base_events.py", line 503, in _make_subprocess_transport
    raise NotImplementedError
NotImplementedError
2025-03-19 22:47:06 - api.routes - ERROR - Error processing URLs: 
2025-03-19 22:48:21 - asyncio - ERROR - Task exception was never retrieved
future: <Task finished name='Task-5' coro=<Connection.run() done, defined at C:\Users\mohdi\AppData\Local\Packages\PythonSoftwareFoundation.Python.3.11_qbz5n2kfra8p0\LocalCache\local-packages\Python311\site-packages\playwright\_impl\_connection.py:272> exception=NotImplementedError()>
Traceback (most recent call last):
  File "C:\Users\mohdi\AppData\Local\Packages\PythonSoftwareFoundation.Python.3.11_qbz5n2kfra8p0\LocalCache\local-packages\Python311\site-packages\playwright\_impl\_connection.py", line 279, in run
    await self._transport.connect()
  File "C:\Users\mohdi\AppData\Local\Packages\PythonSoftwareFoundation.Python.3.11_qbz5n2kfra8p0\LocalCache\local-packages\Python311\site-packages\playwright\_impl\_transport.py", line 133, in connect
    raise exc
  File "C:\Users\mohdi\AppData\Local\Packages\PythonSoftwareFoundation.Python.3.11_qbz5n2kfra8p0\LocalCache\local-packages\Python311\site-packages\playwright\_impl\_transport.py", line 120, in connect
    self._proc = await asyncio.create_subprocess_exec(
                 ^^^^^^^^^^^^^^^^^^^^^^^^^^^^^^^^^^^^^
  File "C:\Program Files\WindowsApps\PythonSoftwareFoundation.Python.3.11_3.11.2544.0_x64__qbz5n2kfra8p0\Lib\asyncio\subprocess.py", line 223, in create_subprocess_exec
    transport, protocol = await loop.subprocess_exec(
                          ^^^^^^^^^^^^^^^^^^^^^^^^^^^
  File "C:\Program Files\WindowsApps\PythonSoftwareFoundation.Python.3.11_3.11.2544.0_x64__qbz5n2kfra8p0\Lib\asyncio\base_events.py", line 1708, in subprocess_exec
    transport = await self._make_subprocess_transport(
                ^^^^^^^^^^^^^^^^^^^^^^^^^^^^^^^^^^^^^^
  File "C:\Program Files\WindowsApps\PythonSoftwareFoundation.Python.3.11_3.11.2544.0_x64__qbz5n2kfra8p0\Lib\asyncio\base_events.py", line 503, in _make_subprocess_transport
    raise NotImplementedError
NotImplementedError
2025-03-19 22:48:21 - api.routes - ERROR - Error processing URLs: 
2025-03-19 22:49:44 - asyncio - ERROR - Task exception was never retrieved
future: <Task finished name='Task-5' coro=<Connection.run() done, defined at C:\Users\mohdi\AppData\Local\Packages\PythonSoftwareFoundation.Python.3.11_qbz5n2kfra8p0\LocalCache\local-packages\Python311\site-packages\playwright\_impl\_connection.py:272> exception=NotImplementedError()>
Traceback (most recent call last):
  File "C:\Users\mohdi\AppData\Local\Packages\PythonSoftwareFoundation.Python.3.11_qbz5n2kfra8p0\LocalCache\local-packages\Python311\site-packages\playwright\_impl\_connection.py", line 279, in run
    await self._transport.connect()
  File "C:\Users\mohdi\AppData\Local\Packages\PythonSoftwareFoundation.Python.3.11_qbz5n2kfra8p0\LocalCache\local-packages\Python311\site-packages\playwright\_impl\_transport.py", line 133, in connect
    raise exc
  File "C:\Users\mohdi\AppData\Local\Packages\PythonSoftwareFoundation.Python.3.11_qbz5n2kfra8p0\LocalCache\local-packages\Python311\site-packages\playwright\_impl\_transport.py", line 120, in connect
    self._proc = await asyncio.create_subprocess_exec(
                 ^^^^^^^^^^^^^^^^^^^^^^^^^^^^^^^^^^^^^
  File "C:\Program Files\WindowsApps\PythonSoftwareFoundation.Python.3.11_3.11.2544.0_x64__qbz5n2kfra8p0\Lib\asyncio\subprocess.py", line 223, in create_subprocess_exec
    transport, protocol = await loop.subprocess_exec(
                          ^^^^^^^^^^^^^^^^^^^^^^^^^^^
  File "C:\Program Files\WindowsApps\PythonSoftwareFoundation.Python.3.11_3.11.2544.0_x64__qbz5n2kfra8p0\Lib\asyncio\base_events.py", line 1708, in subprocess_exec
    transport = await self._make_subprocess_transport(
                ^^^^^^^^^^^^^^^^^^^^^^^^^^^^^^^^^^^^^^
  File "C:\Program Files\WindowsApps\PythonSoftwareFoundation.Python.3.11_3.11.2544.0_x64__qbz5n2kfra8p0\Lib\asyncio\base_events.py", line 503, in _make_subprocess_transport
    raise NotImplementedError
NotImplementedError
2025-03-19 22:49:44 - crawler.crawler_functions - WARNING - Error with crawl4ai: , using fallback HTTP method
2025-03-19 22:49:44 - crawler.crawler_functions - ERROR - Fallback HTTP method also failed: Constructor parameter should be str
2025-03-19 22:49:44 - api.routes - ERROR - Error processing URLs: Failed to crawl https://www.wemark.com.au/: Constructor parameter should be str
2025-03-19 22:51:33 - crawler.crawler_functions - INFO - Attempting to crawl URL: https://www.wemark.com.au/
2025-03-19 22:51:33 - asyncio - ERROR - Task exception was never retrieved
future: <Task finished name='Task-5' coro=<Connection.run() done, defined at C:\Users\mohdi\AppData\Local\Packages\PythonSoftwareFoundation.Python.3.11_qbz5n2kfra8p0\LocalCache\local-packages\Python311\site-packages\playwright\_impl\_connection.py:272> exception=NotImplementedError()>
Traceback (most recent call last):
  File "C:\Users\mohdi\AppData\Local\Packages\PythonSoftwareFoundation.Python.3.11_qbz5n2kfra8p0\LocalCache\local-packages\Python311\site-packages\playwright\_impl\_connection.py", line 279, in run
    await self._transport.connect()
  File "C:\Users\mohdi\AppData\Local\Packages\PythonSoftwareFoundation.Python.3.11_qbz5n2kfra8p0\LocalCache\local-packages\Python311\site-packages\playwright\_impl\_transport.py", line 133, in connect
    raise exc
  File "C:\Users\mohdi\AppData\Local\Packages\PythonSoftwareFoundation.Python.3.11_qbz5n2kfra8p0\LocalCache\local-packages\Python311\site-packages\playwright\_impl\_transport.py", line 120, in connect
    self._proc = await asyncio.create_subprocess_exec(
                 ^^^^^^^^^^^^^^^^^^^^^^^^^^^^^^^^^^^^^
  File "C:\Program Files\WindowsApps\PythonSoftwareFoundation.Python.3.11_3.11.2544.0_x64__qbz5n2kfra8p0\Lib\asyncio\subprocess.py", line 223, in create_subprocess_exec
    transport, protocol = await loop.subprocess_exec(
                          ^^^^^^^^^^^^^^^^^^^^^^^^^^^
  File "C:\Program Files\WindowsApps\PythonSoftwareFoundation.Python.3.11_3.11.2544.0_x64__qbz5n2kfra8p0\Lib\asyncio\base_events.py", line 1708, in subprocess_exec
    transport = await self._make_subprocess_transport(
                ^^^^^^^^^^^^^^^^^^^^^^^^^^^^^^^^^^^^^^
  File "C:\Program Files\WindowsApps\PythonSoftwareFoundation.Python.3.11_3.11.2544.0_x64__qbz5n2kfra8p0\Lib\asyncio\base_events.py", line 503, in _make_subprocess_transport
    raise NotImplementedError
NotImplementedError
2025-03-19 22:51:33 - crawler.crawler_functions - WARNING - Error with crawl4ai: , using fallback HTTP method
2025-03-19 22:51:33 - crawler.crawler_functions - INFO - Sending HTTP request to https://www.wemark.com.au/
2025-03-19 22:51:33 - crawler.crawler_functions - INFO - Successfully crawled https://www.wemark.com.au/ using fallback HTTP method
2025-03-19 22:51:56 - crawler.crawler_functions - INFO - Attempting to crawl URL: https://www.wemark.com.au/
2025-03-19 22:51:56 - asyncio - ERROR - Task exception was never retrieved
future: <Task finished name='Task-14' coro=<Connection.run() done, defined at C:\Users\mohdi\AppData\Local\Packages\PythonSoftwareFoundation.Python.3.11_qbz5n2kfra8p0\LocalCache\local-packages\Python311\site-packages\playwright\_impl\_connection.py:272> exception=NotImplementedError()>
Traceback (most recent call last):
  File "C:\Users\mohdi\AppData\Local\Packages\PythonSoftwareFoundation.Python.3.11_qbz5n2kfra8p0\LocalCache\local-packages\Python311\site-packages\playwright\_impl\_connection.py", line 279, in run
    await self._transport.connect()
  File "C:\Users\mohdi\AppData\Local\Packages\PythonSoftwareFoundation.Python.3.11_qbz5n2kfra8p0\LocalCache\local-packages\Python311\site-packages\playwright\_impl\_transport.py", line 133, in connect
    raise exc
  File "C:\Users\mohdi\AppData\Local\Packages\PythonSoftwareFoundation.Python.3.11_qbz5n2kfra8p0\LocalCache\local-packages\Python311\site-packages\playwright\_impl\_transport.py", line 120, in connect
    self._proc = await asyncio.create_subprocess_exec(
                 ^^^^^^^^^^^^^^^^^^^^^^^^^^^^^^^^^^^^^
  File "C:\Program Files\WindowsApps\PythonSoftwareFoundation.Python.3.11_3.11.2544.0_x64__qbz5n2kfra8p0\Lib\asyncio\subprocess.py", line 223, in create_subprocess_exec
    transport, protocol = await loop.subprocess_exec(
                          ^^^^^^^^^^^^^^^^^^^^^^^^^^^
  File "C:\Program Files\WindowsApps\PythonSoftwareFoundation.Python.3.11_3.11.2544.0_x64__qbz5n2kfra8p0\Lib\asyncio\base_events.py", line 1708, in subprocess_exec
    transport = await self._make_subprocess_transport(
                ^^^^^^^^^^^^^^^^^^^^^^^^^^^^^^^^^^^^^^
  File "C:\Program Files\WindowsApps\PythonSoftwareFoundation.Python.3.11_3.11.2544.0_x64__qbz5n2kfra8p0\Lib\asyncio\base_events.py", line 503, in _make_subprocess_transport
    raise NotImplementedError
NotImplementedError
2025-03-19 22:51:56 - crawler.crawler_functions - WARNING - Error with crawl4ai: , using fallback HTTP method
2025-03-19 22:51:56 - crawler.crawler_functions - INFO - Sending HTTP request to https://www.wemark.com.au/
2025-03-19 22:51:56 - crawler.crawler_functions - INFO - Successfully crawled https://www.wemark.com.au/ using fallback HTTP method
2025-03-19 22:52:38 - crawler.crawler_functions - INFO - Attempting to crawl URL: https://stepsharp.com/
2025-03-19 22:52:38 - asyncio - ERROR - Task exception was never retrieved
future: <Task finished name='Task-20' coro=<Connection.run() done, defined at C:\Users\mohdi\AppData\Local\Packages\PythonSoftwareFoundation.Python.3.11_qbz5n2kfra8p0\LocalCache\local-packages\Python311\site-packages\playwright\_impl\_connection.py:272> exception=NotImplementedError()>
Traceback (most recent call last):
  File "C:\Users\mohdi\AppData\Local\Packages\PythonSoftwareFoundation.Python.3.11_qbz5n2kfra8p0\LocalCache\local-packages\Python311\site-packages\playwright\_impl\_connection.py", line 279, in run
    await self._transport.connect()
  File "C:\Users\mohdi\AppData\Local\Packages\PythonSoftwareFoundation.Python.3.11_qbz5n2kfra8p0\LocalCache\local-packages\Python311\site-packages\playwright\_impl\_transport.py", line 133, in connect
    raise exc
  File "C:\Users\mohdi\AppData\Local\Packages\PythonSoftwareFoundation.Python.3.11_qbz5n2kfra8p0\LocalCache\local-packages\Python311\site-packages\playwright\_impl\_transport.py", line 120, in connect
    self._proc = await asyncio.create_subprocess_exec(
                 ^^^^^^^^^^^^^^^^^^^^^^^^^^^^^^^^^^^^^
  File "C:\Program Files\WindowsApps\PythonSoftwareFoundation.Python.3.11_3.11.2544.0_x64__qbz5n2kfra8p0\Lib\asyncio\subprocess.py", line 223, in create_subprocess_exec
    transport, protocol = await loop.subprocess_exec(
                          ^^^^^^^^^^^^^^^^^^^^^^^^^^^
  File "C:\Program Files\WindowsApps\PythonSoftwareFoundation.Python.3.11_3.11.2544.0_x64__qbz5n2kfra8p0\Lib\asyncio\base_events.py", line 1708, in subprocess_exec
    transport = await self._make_subprocess_transport(
                ^^^^^^^^^^^^^^^^^^^^^^^^^^^^^^^^^^^^^^
  File "C:\Program Files\WindowsApps\PythonSoftwareFoundation.Python.3.11_3.11.2544.0_x64__qbz5n2kfra8p0\Lib\asyncio\base_events.py", line 503, in _make_subprocess_transport
    raise NotImplementedError
NotImplementedError
2025-03-19 22:52:38 - crawler.crawler_functions - WARNING - Error with crawl4ai: , using fallback HTTP method
2025-03-19 22:52:38 - crawler.crawler_functions - INFO - Sending HTTP request to https://stepsharp.com/
2025-03-19 22:52:40 - crawler.crawler_functions - INFO - Successfully crawled https://stepsharp.com/ using fallback HTTP method
2025-03-19 22:52:59 - crawler.crawler_functions - INFO - Attempting to crawl URL: https://www.wemark.com.au/properties?pstatus=current&ptype=rental&plimit=9&title=Current-Properties-For-Rent
2025-03-19 22:52:59 - asyncio - ERROR - Task exception was never retrieved
future: <Task finished name='Task-29' coro=<Connection.run() done, defined at C:\Users\mohdi\AppData\Local\Packages\PythonSoftwareFoundation.Python.3.11_qbz5n2kfra8p0\LocalCache\local-packages\Python311\site-packages\playwright\_impl\_connection.py:272> exception=NotImplementedError()>
Traceback (most recent call last):
  File "C:\Users\mohdi\AppData\Local\Packages\PythonSoftwareFoundation.Python.3.11_qbz5n2kfra8p0\LocalCache\local-packages\Python311\site-packages\playwright\_impl\_connection.py", line 279, in run
    await self._transport.connect()
  File "C:\Users\mohdi\AppData\Local\Packages\PythonSoftwareFoundation.Python.3.11_qbz5n2kfra8p0\LocalCache\local-packages\Python311\site-packages\playwright\_impl\_transport.py", line 133, in connect
    raise exc
  File "C:\Users\mohdi\AppData\Local\Packages\PythonSoftwareFoundation.Python.3.11_qbz5n2kfra8p0\LocalCache\local-packages\Python311\site-packages\playwright\_impl\_transport.py", line 120, in connect
    self._proc = await asyncio.create_subprocess_exec(
                 ^^^^^^^^^^^^^^^^^^^^^^^^^^^^^^^^^^^^^
  File "C:\Program Files\WindowsApps\PythonSoftwareFoundation.Python.3.11_3.11.2544.0_x64__qbz5n2kfra8p0\Lib\asyncio\subprocess.py", line 223, in create_subprocess_exec
    transport, protocol = await loop.subprocess_exec(
                          ^^^^^^^^^^^^^^^^^^^^^^^^^^^
  File "C:\Program Files\WindowsApps\PythonSoftwareFoundation.Python.3.11_3.11.2544.0_x64__qbz5n2kfra8p0\Lib\asyncio\base_events.py", line 1708, in subprocess_exec
    transport = await self._make_subprocess_transport(
                ^^^^^^^^^^^^^^^^^^^^^^^^^^^^^^^^^^^^^^
  File "C:\Program Files\WindowsApps\PythonSoftwareFoundation.Python.3.11_3.11.2544.0_x64__qbz5n2kfra8p0\Lib\asyncio\base_events.py", line 503, in _make_subprocess_transport
    raise NotImplementedError
NotImplementedError
2025-03-19 22:52:59 - crawler.crawler_functions - WARNING - Error with crawl4ai: , using fallback HTTP method
2025-03-19 22:52:59 - crawler.crawler_functions - INFO - Sending HTTP request to https://www.wemark.com.au/properties?pstatus=current&ptype=rental&plimit=9&title=Current-Properties-For-Rent
2025-03-19 22:52:59 - crawler.crawler_functions - INFO - Successfully crawled https://www.wemark.com.au/properties?pstatus=current&ptype=rental&plimit=9&title=Current-Properties-For-Rent using fallback HTTP method
2025-03-19 22:56:28 - crawler.crawler_functions - INFO - Attempting to crawl URL: https://www.wemark.com.au/properties?pstatus=current&ptype=rental&plimit=9&title=Current-Properties-For-Rent
2025-03-19 22:56:28 - asyncio - ERROR - Task exception was never retrieved
future: <Task finished name='Task-5' coro=<Connection.run() done, defined at C:\Users\mohdi\AppData\Local\Packages\PythonSoftwareFoundation.Python.3.11_qbz5n2kfra8p0\LocalCache\local-packages\Python311\site-packages\playwright\_impl\_connection.py:272> exception=NotImplementedError()>
Traceback (most recent call last):
  File "C:\Users\mohdi\AppData\Local\Packages\PythonSoftwareFoundation.Python.3.11_qbz5n2kfra8p0\LocalCache\local-packages\Python311\site-packages\playwright\_impl\_connection.py", line 279, in run
    await self._transport.connect()
  File "C:\Users\mohdi\AppData\Local\Packages\PythonSoftwareFoundation.Python.3.11_qbz5n2kfra8p0\LocalCache\local-packages\Python311\site-packages\playwright\_impl\_transport.py", line 133, in connect
    raise exc
  File "C:\Users\mohdi\AppData\Local\Packages\PythonSoftwareFoundation.Python.3.11_qbz5n2kfra8p0\LocalCache\local-packages\Python311\site-packages\playwright\_impl\_transport.py", line 120, in connect
    self._proc = await asyncio.create_subprocess_exec(
                 ^^^^^^^^^^^^^^^^^^^^^^^^^^^^^^^^^^^^^
  File "C:\Program Files\WindowsApps\PythonSoftwareFoundation.Python.3.11_3.11.2544.0_x64__qbz5n2kfra8p0\Lib\asyncio\subprocess.py", line 223, in create_subprocess_exec
    transport, protocol = await loop.subprocess_exec(
                          ^^^^^^^^^^^^^^^^^^^^^^^^^^^
  File "C:\Program Files\WindowsApps\PythonSoftwareFoundation.Python.3.11_3.11.2544.0_x64__qbz5n2kfra8p0\Lib\asyncio\base_events.py", line 1708, in subprocess_exec
    transport = await self._make_subprocess_transport(
                ^^^^^^^^^^^^^^^^^^^^^^^^^^^^^^^^^^^^^^
  File "C:\Program Files\WindowsApps\PythonSoftwareFoundation.Python.3.11_3.11.2544.0_x64__qbz5n2kfra8p0\Lib\asyncio\base_events.py", line 503, in _make_subprocess_transport
    raise NotImplementedError
NotImplementedError
2025-03-19 22:56:28 - crawler.crawler_functions - WARNING - Error with crawl4ai: , using fallback HTTP method
2025-03-19 22:56:28 - crawler.crawler_functions - INFO - Sending HTTP request to https://www.wemark.com.au/properties?pstatus=current&ptype=rental&plimit=9&title=Current-Properties-For-Rent
2025-03-19 22:56:29 - crawler.crawler_functions - INFO - Fetched 8 additional resources
2025-03-19 22:56:29 - crawler.crawler_functions - INFO - Waiting 8 seconds for dynamic content
2025-03-19 22:56:43 - crawler.crawler_functions - INFO - Successfully crawled https://www.wemark.com.au/properties?pstatus=current&ptype=rental&plimit=9&title=Current-Properties-For-Rent using enhanced fallback HTTP method
2025-03-21 23:28:11 - crawler.crawler_functions - INFO - Attempting to crawl URL: https://www.wemark.com.au/
2025-03-21 23:28:11 - asyncio - ERROR - Task exception was never retrieved
future: <Task finished name='Task-6' coro=<Connection.run() done, defined at C:\Users\mohdi\AppData\Local\Packages\PythonSoftwareFoundation.Python.3.11_qbz5n2kfra8p0\LocalCache\local-packages\Python311\site-packages\playwright\_impl\_connection.py:272> exception=NotImplementedError()>
Traceback (most recent call last):
  File "C:\Users\mohdi\AppData\Local\Packages\PythonSoftwareFoundation.Python.3.11_qbz5n2kfra8p0\LocalCache\local-packages\Python311\site-packages\playwright\_impl\_connection.py", line 279, in run
    await self._transport.connect()
  File "C:\Users\mohdi\AppData\Local\Packages\PythonSoftwareFoundation.Python.3.11_qbz5n2kfra8p0\LocalCache\local-packages\Python311\site-packages\playwright\_impl\_transport.py", line 133, in connect
    raise exc
  File "C:\Users\mohdi\AppData\Local\Packages\PythonSoftwareFoundation.Python.3.11_qbz5n2kfra8p0\LocalCache\local-packages\Python311\site-packages\playwright\_impl\_transport.py", line 120, in connect
    self._proc = await asyncio.create_subprocess_exec(
                 ^^^^^^^^^^^^^^^^^^^^^^^^^^^^^^^^^^^^^
  File "C:\Program Files\WindowsApps\PythonSoftwareFoundation.Python.3.11_3.11.2544.0_x64__qbz5n2kfra8p0\Lib\asyncio\subprocess.py", line 223, in create_subprocess_exec
    transport, protocol = await loop.subprocess_exec(
                          ^^^^^^^^^^^^^^^^^^^^^^^^^^^
  File "C:\Program Files\WindowsApps\PythonSoftwareFoundation.Python.3.11_3.11.2544.0_x64__qbz5n2kfra8p0\Lib\asyncio\base_events.py", line 1708, in subprocess_exec
    transport = await self._make_subprocess_transport(
                ^^^^^^^^^^^^^^^^^^^^^^^^^^^^^^^^^^^^^^
  File "C:\Program Files\WindowsApps\PythonSoftwareFoundation.Python.3.11_3.11.2544.0_x64__qbz5n2kfra8p0\Lib\asyncio\base_events.py", line 503, in _make_subprocess_transport
    raise NotImplementedError
NotImplementedError
2025-03-21 23:28:11 - crawler.crawler_functions - ERROR - Failed to crawl https://www.wemark.com.au/: 
2025-03-21 23:28:11 - api.routes - ERROR - Error processing URL https://www.wemark.com.au/: Failed to crawl https://www.wemark.com.au/: 
2025-03-21 23:28:17 - crawler.crawler_functions - INFO - Attempting to crawl URL: https://www.wemark.com.au/
2025-03-21 23:28:17 - asyncio - ERROR - Task exception was never retrieved
future: <Task finished name='Task-10' coro=<Connection.run() done, defined at C:\Users\mohdi\AppData\Local\Packages\PythonSoftwareFoundation.Python.3.11_qbz5n2kfra8p0\LocalCache\local-packages\Python311\site-packages\playwright\_impl\_connection.py:272> exception=NotImplementedError()>
Traceback (most recent call last):
  File "C:\Users\mohdi\AppData\Local\Packages\PythonSoftwareFoundation.Python.3.11_qbz5n2kfra8p0\LocalCache\local-packages\Python311\site-packages\playwright\_impl\_connection.py", line 279, in run
    await self._transport.connect()
  File "C:\Users\mohdi\AppData\Local\Packages\PythonSoftwareFoundation.Python.3.11_qbz5n2kfra8p0\LocalCache\local-packages\Python311\site-packages\playwright\_impl\_transport.py", line 133, in connect
    raise exc
  File "C:\Users\mohdi\AppData\Local\Packages\PythonSoftwareFoundation.Python.3.11_qbz5n2kfra8p0\LocalCache\local-packages\Python311\site-packages\playwright\_impl\_transport.py", line 120, in connect
    self._proc = await asyncio.create_subprocess_exec(
                 ^^^^^^^^^^^^^^^^^^^^^^^^^^^^^^^^^^^^^
  File "C:\Program Files\WindowsApps\PythonSoftwareFoundation.Python.3.11_3.11.2544.0_x64__qbz5n2kfra8p0\Lib\asyncio\subprocess.py", line 223, in create_subprocess_exec
    transport, protocol = await loop.subprocess_exec(
                          ^^^^^^^^^^^^^^^^^^^^^^^^^^^
  File "C:\Program Files\WindowsApps\PythonSoftwareFoundation.Python.3.11_3.11.2544.0_x64__qbz5n2kfra8p0\Lib\asyncio\base_events.py", line 1708, in subprocess_exec
    transport = await self._make_subprocess_transport(
                ^^^^^^^^^^^^^^^^^^^^^^^^^^^^^^^^^^^^^^
  File "C:\Program Files\WindowsApps\PythonSoftwareFoundation.Python.3.11_3.11.2544.0_x64__qbz5n2kfra8p0\Lib\asyncio\base_events.py", line 503, in _make_subprocess_transport
    raise NotImplementedError
NotImplementedError
2025-03-21 23:28:17 - crawler.crawler_functions - ERROR - Failed to crawl https://www.wemark.com.au/: 
2025-03-21 23:28:17 - api.routes - ERROR - Error processing URL https://www.wemark.com.au/: Failed to crawl https://www.wemark.com.au/: 
2025-03-21 23:28:18 - crawler.crawler_functions - INFO - Attempting to crawl URL: https://www.wemark.com.au/
2025-03-21 23:28:18 - asyncio - ERROR - Task exception was never retrieved
future: <Task finished name='Task-12' coro=<Connection.run() done, defined at C:\Users\mohdi\AppData\Local\Packages\PythonSoftwareFoundation.Python.3.11_qbz5n2kfra8p0\LocalCache\local-packages\Python311\site-packages\playwright\_impl\_connection.py:272> exception=NotImplementedError()>
Traceback (most recent call last):
  File "C:\Users\mohdi\AppData\Local\Packages\PythonSoftwareFoundation.Python.3.11_qbz5n2kfra8p0\LocalCache\local-packages\Python311\site-packages\playwright\_impl\_connection.py", line 279, in run
    await self._transport.connect()
  File "C:\Users\mohdi\AppData\Local\Packages\PythonSoftwareFoundation.Python.3.11_qbz5n2kfra8p0\LocalCache\local-packages\Python311\site-packages\playwright\_impl\_transport.py", line 133, in connect
    raise exc
  File "C:\Users\mohdi\AppData\Local\Packages\PythonSoftwareFoundation.Python.3.11_qbz5n2kfra8p0\LocalCache\local-packages\Python311\site-packages\playwright\_impl\_transport.py", line 120, in connect
    self._proc = await asyncio.create_subprocess_exec(
                 ^^^^^^^^^^^^^^^^^^^^^^^^^^^^^^^^^^^^^
  File "C:\Program Files\WindowsApps\PythonSoftwareFoundation.Python.3.11_3.11.2544.0_x64__qbz5n2kfra8p0\Lib\asyncio\subprocess.py", line 223, in create_subprocess_exec
    transport, protocol = await loop.subprocess_exec(
                          ^^^^^^^^^^^^^^^^^^^^^^^^^^^
  File "C:\Program Files\WindowsApps\PythonSoftwareFoundation.Python.3.11_3.11.2544.0_x64__qbz5n2kfra8p0\Lib\asyncio\base_events.py", line 1708, in subprocess_exec
    transport = await self._make_subprocess_transport(
                ^^^^^^^^^^^^^^^^^^^^^^^^^^^^^^^^^^^^^^
  File "C:\Program Files\WindowsApps\PythonSoftwareFoundation.Python.3.11_3.11.2544.0_x64__qbz5n2kfra8p0\Lib\asyncio\base_events.py", line 503, in _make_subprocess_transport
    raise NotImplementedError
NotImplementedError
2025-03-21 23:28:18 - crawler.crawler_functions - ERROR - Failed to crawl https://www.wemark.com.au/: 
2025-03-21 23:28:18 - api.routes - ERROR - Error processing URL https://www.wemark.com.au/: Failed to crawl https://www.wemark.com.au/: 
